[2024-05-21T14:58:08.246+0530] {local_task_job_runner.py:120} INFO - ::group::Pre task execution logs
[2024-05-21T14:58:08.260+0530] {taskinstance.py:2076} INFO - Dependencies all met for dep_context=non-requeueable deps ti=<TaskInstance: etl_dag.extract_task manual__2024-05-21T09:12:34.180878+00:00 [queued]>
[2024-05-21T14:58:08.263+0530] {taskinstance.py:2076} INFO - Dependencies all met for dep_context=requeueable deps ti=<TaskInstance: etl_dag.extract_task manual__2024-05-21T09:12:34.180878+00:00 [queued]>
[2024-05-21T14:58:08.263+0530] {taskinstance.py:2306} INFO - Starting attempt 4 of 5
[2024-05-21T14:58:08.323+0530] {taskinstance.py:2330} INFO - Executing <Task(PythonOperator): extract_task> on 2024-05-21 09:12:34.180878+00:00
[2024-05-21T14:58:08.326+0530] {standard_task_runner.py:63} INFO - Started process 69103 to run task
[2024-05-21T14:58:08.328+0530] {standard_task_runner.py:90} INFO - Running: ['airflow', 'tasks', 'run', 'etl_dag', 'extract_task', 'manual__2024-05-21T09:12:34.180878+00:00', '--job-id', '35', '--raw', '--subdir', 'DAGS_FOLDER/etl_dag.py', '--cfg-path', '/tmp/tmp1cv_wkcp']
[2024-05-21T14:58:08.330+0530] {standard_task_runner.py:91} INFO - Job 35: Subtask extract_task
[2024-05-21T14:58:08.411+0530] {task_command.py:426} INFO - Running <TaskInstance: etl_dag.extract_task manual__2024-05-21T09:12:34.180878+00:00 [running]> on host prince-5192
[2024-05-21T14:58:08.692+0530] {taskinstance.py:2648} INFO - Exporting env vars: AIRFLOW_CTX_DAG_EMAIL='prince.yadav@tothenew.com' AIRFLOW_CTX_DAG_OWNER='airflow' AIRFLOW_CTX_DAG_ID='etl_dag' AIRFLOW_CTX_TASK_ID='extract_task' AIRFLOW_CTX_EXECUTION_DATE='2024-05-21T09:12:34.180878+00:00' AIRFLOW_CTX_TRY_NUMBER='4' AIRFLOW_CTX_DAG_RUN_ID='manual__2024-05-21T09:12:34.180878+00:00'
[2024-05-21T14:58:08.692+0530] {taskinstance.py:430} INFO - ::endgroup::
[2024-05-21T14:58:08.700+0530] {logging_mixin.py:188} INFO - /////////////////// 	 Extracting Data from S3 Bucket  	///////////////////////////
[2024-05-21T14:58:08.704+0530] {base.py:84} INFO - Using connection ID 'aws_default' for task execution.
[2024-05-21T14:58:08.704+0530] {connection_wrapper.py:384} INFO - AWS Connection (conn_id='aws_default', conn_type='aws') credentials retrieved from login and password.
[2024-05-21T14:58:10.513+0530] {logging_mixin.py:188} INFO - /////////////////// 	 Reading data 	///////////////////////////
[2024-05-21T14:58:10.895+0530] {taskinstance.py:441} INFO - ::group::Post task execution logs
[2024-05-21T14:58:10.895+0530] {taskinstance.py:2905} ERROR - Task failed with exception
Traceback (most recent call last):
  File "/home/prince/airflow-workspace/env/lib/python3.10/site-packages/airflow/models/taskinstance.py", line 465, in _execute_task
    result = _execute_callable(context=context, **execute_callable_kwargs)
  File "/home/prince/airflow-workspace/env/lib/python3.10/site-packages/airflow/models/taskinstance.py", line 432, in _execute_callable
    return execute_callable(context=context, **execute_callable_kwargs)
  File "/home/prince/airflow-workspace/env/lib/python3.10/site-packages/airflow/models/baseoperator.py", line 400, in wrapper
    return func(self, *args, **kwargs)
  File "/home/prince/airflow-workspace/env/lib/python3.10/site-packages/airflow/operators/python.py", line 235, in execute
    return_value = self.execute_callable()
  File "/home/prince/airflow-workspace/env/lib/python3.10/site-packages/airflow/operators/python.py", line 252, in execute_callable
    return self.python_callable(*self.op_args, **self.op_kwargs)
  File "/home/prince/airflow-workspace/airflow/scripts/extract.py", line 14, in extract_from_s3
    print(f"{json.loads(data)}\n")
  File "/usr/lib/python3.10/json/__init__.py", line 341, in loads
    s = s.decode(detect_encoding(s), 'surrogatepass')
UnicodeDecodeError: 'utf-8' codec can't decode byte 0xf8 in position 3532319: invalid start byte
[2024-05-21T14:58:10.898+0530] {taskinstance.py:1206} INFO - Marking task as UP_FOR_RETRY. dag_id=etl_dag, task_id=extract_task, run_id=manual__2024-05-21T09:12:34.180878+00:00, execution_date=20240521T091234, start_date=20240521T092808, end_date=20240521T092810
[2024-05-21T14:58:10.961+0530] {standard_task_runner.py:110} ERROR - Failed to execute job 35 for task extract_task ('utf-8' codec can't decode byte 0xf8 in position 3532319: invalid start byte; 69103)
[2024-05-21T14:58:10.988+0530] {local_task_job_runner.py:240} INFO - Task exited with return code 1
[2024-05-21T14:58:10.996+0530] {taskinstance.py:3498} INFO - 0 downstream tasks scheduled from follow-on schedule check
[2024-05-21T14:58:10.997+0530] {local_task_job_runner.py:222} INFO - ::endgroup::
