[2024-05-21T15:13:03.893+0530] {local_task_job_runner.py:120} INFO - ::group::Pre task execution logs
[2024-05-21T15:13:03.906+0530] {taskinstance.py:2076} INFO - Dependencies all met for dep_context=non-requeueable deps ti=<TaskInstance: etl_dag.email_notify manual__2024-05-21T09:12:34.180878+00:00 [queued]>
[2024-05-21T15:13:03.910+0530] {taskinstance.py:2076} INFO - Dependencies all met for dep_context=requeueable deps ti=<TaskInstance: etl_dag.email_notify manual__2024-05-21T09:12:34.180878+00:00 [queued]>
[2024-05-21T15:13:03.910+0530] {taskinstance.py:2306} INFO - Starting attempt 2 of 2
[2024-05-21T15:13:04.371+0530] {taskinstance.py:2330} INFO - Executing <Task(EmailOperator): email_notify> on 2024-05-21 09:12:34.180878+00:00
[2024-05-21T15:13:04.374+0530] {standard_task_runner.py:63} INFO - Started process 78341 to run task
[2024-05-21T15:13:04.376+0530] {standard_task_runner.py:90} INFO - Running: ['airflow', 'tasks', 'run', 'etl_dag', 'email_notify', 'manual__2024-05-21T09:12:34.180878+00:00', '--job-id', '43', '--raw', '--subdir', 'DAGS_FOLDER/etl_dag.py', '--cfg-path', '/tmp/tmpq427rs18']
[2024-05-21T15:13:04.377+0530] {standard_task_runner.py:91} INFO - Job 43: Subtask email_notify
[2024-05-21T15:13:04.486+0530] {task_command.py:426} INFO - Running <TaskInstance: etl_dag.email_notify manual__2024-05-21T09:12:34.180878+00:00 [running]> on host prince-5192
[2024-05-21T15:13:04.580+0530] {taskinstance.py:2648} INFO - Exporting env vars: AIRFLOW_CTX_DAG_EMAIL='prince.yadav@tothenew.com' AIRFLOW_CTX_DAG_OWNER='airflow' AIRFLOW_CTX_DAG_ID='etl_dag' AIRFLOW_CTX_TASK_ID='email_notify' AIRFLOW_CTX_EXECUTION_DATE='2024-05-21T09:12:34.180878+00:00' AIRFLOW_CTX_TRY_NUMBER='2' AIRFLOW_CTX_DAG_RUN_ID='manual__2024-05-21T09:12:34.180878+00:00'
[2024-05-21T15:13:04.581+0530] {taskinstance.py:430} INFO - ::endgroup::
[2024-05-21T15:13:04.594+0530] {logging_mixin.py:188} WARNING - /home/prince/airflow-workspace/env/lib/python3.10/site-packages/airflow/utils/email.py:154 RemovedInAirflow3Warning: Fetching SMTP credentials from configuration variables will be deprecated in a future release. Please set credentials using a connection instead.
[2024-05-21T15:13:04.595+0530] {configuration.py:1050} WARNING - section/key [smtp/smtp_user] not found in config
[2024-05-21T15:13:04.595+0530] {email.py:271} INFO - Email alerting: attempt 1
[2024-05-21T15:13:04.595+0530] {taskinstance.py:441} INFO - ::group::Post task execution logs
[2024-05-21T15:13:04.595+0530] {taskinstance.py:2905} ERROR - Task failed with exception
Traceback (most recent call last):
  File "/home/prince/airflow-workspace/env/lib/python3.10/site-packages/airflow/models/taskinstance.py", line 465, in _execute_task
    result = _execute_callable(context=context, **execute_callable_kwargs)
  File "/home/prince/airflow-workspace/env/lib/python3.10/site-packages/airflow/models/taskinstance.py", line 432, in _execute_callable
    return execute_callable(context=context, **execute_callable_kwargs)
  File "/home/prince/airflow-workspace/env/lib/python3.10/site-packages/airflow/models/baseoperator.py", line 400, in wrapper
    return func(self, *args, **kwargs)
  File "/home/prince/airflow-workspace/env/lib/python3.10/site-packages/airflow/operators/email.py", line 79, in execute
    send_email(
  File "/home/prince/airflow-workspace/env/lib/python3.10/site-packages/airflow/utils/email.py", line 80, in send_email
    return backend(
  File "/home/prince/airflow-workspace/env/lib/python3.10/site-packages/airflow/utils/email.py", line 154, in send_email_smtp
    send_mime_email(e_from=mail_from, e_to=recipients, mime_msg=msg, conn_id=conn_id, dryrun=dryrun)
  File "/home/prince/airflow-workspace/env/lib/python3.10/site-packages/airflow/utils/email.py", line 273, in send_mime_email
    smtp_conn = _get_smtp_connection(smtp_host, smtp_port, smtp_timeout, smtp_ssl)
  File "/home/prince/airflow-workspace/env/lib/python3.10/site-packages/airflow/utils/email.py", line 317, in _get_smtp_connection
    return smtplib.SMTP(host=host, port=port, timeout=timeout)
  File "/usr/lib/python3.10/smtplib.py", line 255, in __init__
    (code, msg) = self.connect(host, port)
  File "/usr/lib/python3.10/smtplib.py", line 341, in connect
    self.sock = self._get_socket(host, port, self.timeout)
  File "/usr/lib/python3.10/smtplib.py", line 312, in _get_socket
    return socket.create_connection((host, port), timeout,
  File "/usr/lib/python3.10/socket.py", line 845, in create_connection
    raise err
  File "/usr/lib/python3.10/socket.py", line 833, in create_connection
    sock.connect(sa)
ConnectionRefusedError: [Errno 111] Connection refused
[2024-05-21T15:13:04.603+0530] {taskinstance.py:1206} INFO - Marking task as FAILED. dag_id=etl_dag, task_id=email_notify, run_id=manual__2024-05-21T09:12:34.180878+00:00, execution_date=20240521T091234, start_date=20240521T094303, end_date=20240521T094304
[2024-05-21T15:13:04.667+0530] {standard_task_runner.py:110} ERROR - Failed to execute job 43 for task email_notify ([Errno 111] Connection refused; 78341)
[2024-05-21T15:13:04.709+0530] {local_task_job_runner.py:240} INFO - Task exited with return code 1
[2024-05-21T15:13:04.717+0530] {taskinstance.py:3498} INFO - 0 downstream tasks scheduled from follow-on schedule check
[2024-05-21T15:13:04.717+0530] {local_task_job_runner.py:222} INFO - ::endgroup::
